Workbook

Sheet HR_Roster
A1: EmployeeID | B1: FirstName | C1: LastName | D1: Department | E1: HireDate | F1: Status | G1: TerminationDate | H1: logged in
A2: 100001 | B2: Anthony | C2: Smith | D2: HR | E2: 45472 | F2: Active
A3: 100002 | B3: Anthony | C3: Jones | D3: Marketing | E3: 43612 | F3: Active
A4: 100003 | B4: Joshua | C4: Rodriguez | D4: Finance | E4: 43451 | F4: Active
A5: 100004 | B5: Thomas | C5: Garcia | D5: Sales | E5: 43349 | F5: Active
A6: 100005 | B6: Donald | C6: Gonzalez | D6: Marketing | E6: 43237 | F6: Active
A7: 100006 | B7: James | C7: Wilson | D7: Finance | E7: 44646 | F7: Active
A8: 100007 | B8: Richard | C8: Jones | D8: Finance | E8: 44384 | F8: Active
A9: 100008 | B9: John | C9: Rodriguez | D9: Finance | E9: 43367 | F9: Active
A10: 100009 | B10: Paul | C10: Jackson | D10: HR | E10: 43623 | F10: Active
A11: 100010 | B11: James | C11: Anderson | D11: Finance | E11: 43354 | F11: Active
A12: 100011 | B12: Christopher | C12: Lopez | D12: Sales | E12: 44911 | F12: Active
A13: 100012 | B13: Richard | C13: Davis | D13: IT | E13: 43325 | F13: Active
... A113: 100112 | B113: Anthony | C113: Garcia | D113: IT | E113: 44044 | F113: Active
A114: 100113 | B114: William | C114: Martin | D114: Finance | E114: 45011 | F114: Terminated | G114: 45477
A115: 100114 | B115: Richard | C115: Miller | D115: Operations | E115: 44080 | F115: Active
A116: 100115 | B116: Steven | C116: Jackson | D116: Marketing | E116: 45070 | F116: Active
A117: 100116 | B117: Andrew | C117: Johnson | D117: Marketing | E117: 44458 | F117: Active
A118: 100117 | B118: Joshua | C118: Anderson | D118: Sales | E118: 44640 | F118: Active
A119: 100118 | B119: Charles | C119: Anderson | D119: Sales | E119: 43941 | F119: Active
A120: 100119 | B120: Andrew | C120: Davis | D120: Marketing | E120: 44740 | F120: Active
A121: 100120 | B121: Andrew | C121: Thomas | D121: HR | E121: 43855 | F121: Active
A122: 100121 | B122: John | C122: Jones | D122: Sales | E122: 43128 | F122: Active
A123: 100122 | B123: Joshua | C123: Jackson | D123: HR | E123: 44587 | F123: Active
A124: 100123 | B124: Mark | C124: Hernandez | D124: Operations | E124: 43141 | F124: Active
A125: 100124 | B125: James | C125: Rodriguez | D125: Operations | E125: 43403 | F125: Active
A126: 100125 | B126: Robert | C126: Lopez | D126: Marketing | E126: 44566 | F126: Active
... A156: 100155 | B156: Andrew | C156: Rodriguez | D156: Operations | E156: 44653 | F156: Active
A157: 100156 | B157: Mark | C157: Davis | D157: Marketing | E157: 43555 | F157: Terminated | G157: 44278
A158: 100157 | B158: David | C158: Davis | D158: Finance | E158: 43962 | F158: Active
A159: 100158 | B159: John | C159: Thomas | D159: IT | E159: 44350 | F159: Active
A160: 100159 | B160: Robert | C160: Martin | D160: HR | E160: 44969 | F160: Active
A161: 100160 | B161: Mark | C161: Hernandez | D161: Marketing | E161: 44084 | F161: Active
A162: 100161 | B162: James | C162: Miller | D162: HR | E162: 44615 | F162: Terminated | G162: 45407
A163: 100162 | B163: Paul | C163: Williams | D163: IT | E163: 43802 | F163: Active
A164: 100163 | B164: Steven | C164: Brown | D164: Operations | E164: 45259 | F164: Active
A165: 100164 | B165: Andrew | C165: Brown | D165: Marketing | E165: 44877 | F165: Active
A166: 100165 | B166: Charles | C166: Jones | D166: HR | E166: 43368 | F166: Terminated | G166: 43640
A167: 100166 | B167: Steven | C167: Davis | D167: Finance | E167: 43692 | F167: Active
A168: 100167 | B168: James | C168: Lopez | D168: Sales | E168: 43636 | F168: Active
...

Sheet Sheet1
A3: Count of Suspicous Login | B3: Column Labels
A4: Row Labels | B4: Suspicious Login | C4: Grand Total
A5: Salesforce | B5: 98 | C5: 98
A6: SAP | B6: 103 | C6: 103
A7: PayrollSystem | B7: 111 | C7: 111
A8: Oracle | B8: 114 | C8: 114
A9: VPN | B9: 122 | C9: 122
A10: Workday | B10: 122 | C10: 122
A11: Grand Total | B11: 670 | C11: 670

Sheet Practice_Instructions
A1: IT Audit User Access Review Project
A3: Tasks:
A4: 1. Use XLOOKUP to pull employee status into the login table.
A5: 2. Identify terminated employees with active logins.
A6: 3. Use IF / IFERROR to clean and classify records.
A7: 4. Create PivotTables summarizing suspicious logins by system.
A8: 5. Use Conditional Formatting to highlight risky records in red.
A9: 6. Import both CSV files into PostgreSQL / pgAdmin later.

Sheet System_Logins
A1: EmployeeID | B1: SystemName | C1: LoginDate | D1: IP_Address | E1: employee status | F1: Suspicous Login | G1: TerminationDate | H1: Days After Termination
A2: 102326 | B2: PayrollSystem | C2: 45354 | D2: 192.168.12.6 | E2: =_xlfn.XLOOKUP(A2,HR_Roster!$A$2:$A$10001,HR_Roster!$F$2:$F$10001,"no emp found",0) -> Terminated | F2: =IF(AND(E2="Terminated",C2>G2),"Suspicious Login","OK") -> Suspicious Login | G2: =IF(E2="Active","Not Terminated",_xlfn.XLOOKUP(A2,HR_Roster!$A$2:$A$10001,HR_Roster!$G$2:$G$10001)) -> 45292 | H2: =IF(F2="Suspicious Login",C2-G2,"") -> 62
A3: 108584 | B3: Workday | C3: 45690 | D3: 192.168.56.194 | E3: =_xlfn.XLOOKUP(A3,HR_Roster!$A$2:$A$10001,HR_Roster!$F$2:$F$10001,"no emp found",0) -> Active | F3: =IF(AND(E3="Terminated",C3>G3),"Suspicious Login","OK") -> OK | G3: =IF(E3="Active","Not Terminated",_xlfn.XLOOKUP(A3,HR_Roster!$A$2:$A$10001,HR_Roster!$G$2:$G$10001)) -> Not Terminated | H3: =IF(F3="Suspicious Login",C3-G3,"")
A4: 105045 | B4: SAP | C4: 45954 | D4: 192.168.37.54 | E4: =_xlfn.XLOOKUP(A4,HR_Roster!$A$2:$A$10001,HR_Roster!$F$2:$F$10001,"no emp found",0) -> Active | F4: =IF(AND(E4="Terminated",C4>G4),"Suspicious Login","OK") -> OK | G4: =IF(E4="Active","Not Terminated",_xlfn.XLOOKUP(A4,HR_Roster!$A$2:$A$10001,HR_Roster!$G$2:$G$10001)) -> Not Terminated | H4: =IF(F4="Suspicious Login",C4-G4,"")
A5: 107870 | B5: Workday | C5: 45811 | D5: 192.168.46.213 | E5: =_xlfn.XLOOKUP(A5,HR_Roster!$A$2:$A$10001,HR_Roster!$F$2:$F$10001,"no emp found",0) -> Active | F5: =IF(AND(E5="Terminated",C5>G5),"Suspicious Login","OK") -> OK | G5: =IF(E5="Active","Not Terminated",_xlfn.XLOOKUP(A5,HR_Roster!$A$2:$A$10001,HR_Roster!$G$2:$G$10001)) -> Not Terminated | H5: =IF(F5="Suspicious Login",C5-G5,"")
A6: 107082 | B6: PayrollSystem | C6: 45951 | D6: 192.168.45.195 | E6: =_xlfn.XLOOKUP(A6,HR_Roster!$A$2:$A$10001,HR_Roster!$F$2:$F$10001,"no emp found",0) -> Active | F6: =IF(AND(E6="Terminated",C6>G6),"Suspicious Login","OK") -> OK | G6: =IF(E6="Active","Not Terminated",_xlfn.XLOOKUP(A6,HR_Roster!$A$2:$A$10001,HR_Roster!$G$2:$G$10001)) -> Not Terminated | H6: =IF(F6="Suspicious Login",C6-G6,"")
A7: 104567 | B7: Oracle | C7: 45977 | D7: 192.168.26.142 | E7: =_xlfn.XLOOKUP(A7,HR_Roster!$A$2:$A$10001,HR_Roster!$F$2:$F$10001,"no emp found",0) -> Active | F7: =IF(AND(E7="Terminated",C7>G7),"Suspicious Login","OK") -> OK | G7: =IF(E7="Active","Not Terminated",_xlfn.XLOOKUP(A7,HR_Roster!$A$2:$A$10001,HR_Roster!$G$2:$G$10001)) -> Not Terminated | H7: =IF(F7="Suspicious Login",C7-G7,"")
A8: 100062 | B8: PayrollSystem | C8: 45704 | D8: 192.168.98.173 | E8: =_xlfn.XLOOKUP(A8,HR_Roster!$A$2:$A$10001,HR_Roster!$F$2:$F$10001,"no emp found",0) -> Active | F8: =IF(AND(E8="Terminated",C8>G8),"Suspicious Login","OK") -> OK | G8: =IF(E8="Active","Not Terminated",_xlfn.XLOOKUP(A8,HR_Roster!$A$2:$A$10001,HR_Roster!$G$2:$G$10001)) -> Not Terminated | H8: =IF(F8="Suspicious Login",C8-G8,"")
A9: 109458 | B9: Oracle | C9: 45985 | D9: 192.168.233.157 | E9: =_xlfn.XLOOKUP(A9,HR_Roster!$A$2:$A$10001,HR_Roster!$F$2:$F$10001,"no emp found",0) -> Active | F9: =IF(AND(E9="Terminated",C9>G9),"Suspicious Login","OK") -> OK | G9: =IF(E9="Active","Not Terminated",_xlfn.XLOOKUP(A9,HR_Roster!$A$2:$A$10001,HR_Roster!$G$2:$G$10001)) -> Not Terminated | H9: =IF(F9="Suspicious Login",C9-G9,"")
A10: 101931 | B10: PayrollSystem | C10: 45718 | D10: 192.168.178.45 | E10: =_xlfn.XLOOKUP(A10,HR_Roster!$A$2:$A$10001,HR_Roster!$F$2:$F$10001,"no emp found",0) -> Active | F10: =IF(AND(E10="Terminated",C10>G10),"Suspicious Login","OK") -> OK | G10: =IF(E10="Active","Not Terminated",_xlfn.XLOOKUP(A10,HR_Roster!$A$2:$A$10001,HR_Roster!$G$2:$G$10001)) -> Not Terminated | H10: =IF(F10="Suspicious Login",C10-G10,"")
A11: 109378 | B11: Salesforce | C11: 45811 | D11: 192.168.231.68 | E11: =_xlfn.XLOOKUP(A11,HR_Roster!$A$2:$A$10001,HR_Roster!$F$2:$F$10001,"no emp found",0) -> Active | F11: =IF(AND(E11="Terminated",C11>G11),"Suspicious Login","OK") -> OK | G11: =IF(E11="Active","Not Terminated",_xlfn.XLOOKUP(A11,HR_Roster!$A$2:$A$10001,HR_Roster!$G$2:$G$10001)) -> Not Terminated | H11: =IF(F11="Suspicious Login",C11-G11,"")
A12: 100646 | B12: SAP | C12: 45784 | D12: 192.168.254.28 | E12: =_xlfn.XLOOKUP(A12,HR_Roster!$A$2:$A$10001,HR_Roster!$F$2:$F$10001,"no emp found",0) -> Active | F12: =IF(AND(E12="Terminated",C12>G12),"Suspicious Login","OK") -> OK | G12: =IF(E12="Active","Not Terminated",_xlfn.XLOOKUP(A12,HR_Roster!$A$2:$A$10001,HR_Roster!$G$2:$G$10001)) -> Not Terminated | H12: =IF(F12="Suspicious Login",C12-G12,"")
A13: 108887 | B13: VPN | C13: 45737 | D13: 192.168.119.255 | E13: =_xlfn.XLOOKUP(A13,HR_Roster!$A$2:$A$10001,HR_Roster!$F$2:$F$10001,"no emp found",0) -> Active | F13: =IF(AND(E13="Terminated",C13>G13),"Suspicious Login","OK") -> OK | G13: =IF(E13="Active","Not Terminated",_xlfn.XLOOKUP(A13,HR_Roster!$A$2:$A$10001,HR_Roster!$G$2:$G$10001)) -> Not Terminated | H13: =IF(F13="Suspicious Login",C13-G13,"")
... A15001: 103716 | B15001: VPN | C15001: 45284 | D15001: 192.168.53.73 | E15001: =_xlfn.XLOOKUP(A15001,HR_Roster!$A$2:$A$10001,HR_Roster!$F$2:$F$10001,"no emp found",0) -> Terminated | F15001: =IF(AND(E15001="Terminated",C15001>G15001),"Suspicious Login","OK") -> Suspicious Login | G15001: =IF(E15001="Active","Not Terminated",_xlfn.XLOOKUP(A15001,HR_Roster!$A$2:$A$10001,HR_Roster!$G$2:$G$10001)) -> 45265 | H15001: =IF(F15001="Suspicious Login",C15001-G15001,"") -> 19
